Workbook
Name Activity: Lookups!$I$17:$I$23
Name groupsList: Lookups!$C$6:$C$155
Name risknumbers: #REF!
Name riskwords: Lookups!$L$17:$L$20
Name Role: Lookups!$R$5:$R$24
Name sectionList: Lookups!$O$5:$O$9
Name yesnoList: Lookups!$I$5:$I$6

Sheet Instructions
A2: Instructions, hints and ideas - R1
A3: Workflow
A4: Alternative versions of this R1 exist below. Note that you will be navigating away from Excel and may receive a warning. You should always make sure you trust the links you click on before navigating there.
A5: To use the R1 template in Google Sheets, you will need to make your own copy.
A6: Or, you can access the PDF from here.
A7: If you intend to use the online version, the R1 will be open in Preview mode. To open it in your browser ready to add your details, please click on "File > Make a copy" in the top left of your window.
A8: (Move across this row, then down) | B8: 1. Start on the "Event details" tab and enter the details of the participating formations | C8: 2. Add details of the event | D8: 3. Enter the names and details for all of the event personnel. | E8: 4. Enter the numbers of attendees
B9: 5. Then go to the "Risks" tabs. NOTE: A number of people can be logged in to the R1 and work on it simultaneously. | C9: 6. Enter your hazards and controls. Overall event risks in the "Event Risks" tab, then (if relevant) specific activity risks in the other tab. Enter the numbers 1 to 5 for each Consequence or Likelihood cell. The spreadsheet will compute the appropriate risk rating, as per the Risk Matrix. | D9: 7. If a risk is listed in EventRisks, it does NOT need to be repeated in the ActivityRisks tab.
B10: 8. "Sign-off" for your role | C10: 9. The top part of the Sign-off page should be automatically filled. Personnel that need to sign off will need to enter their name, date and Scout number. | D10: 10. Physical signatures are not required if being done online. | E10: 11. Email ScoutsWA Events Coordinator (if necessary) or your line leader when you have completed the form
B11: 12. Save a copy of the form for your records (File>Save As>Select PDF from the drop down menu) | C11: 13. Send a copy to others (if necessary) | D11: 14. Guidelines, instructions and a video are available on MyScout. Search for "R1" in Resources>Documents
A13: Support documents
B14: Risk Assessment Guideline
A16: Ideas
B17: Minor injuries such as cuts, scratches, grazes, bruises can all be on one line - set the risk to the highest value, but they are usually all very similar C & L.
B18: Remember: Controls can affect either the Likelihood or the Consequence. eg: wearing a PFD can reduce the consequence of falling in the water because the time under water is likely to be less.
B19: If there is a Standard Operating Procedure for the activity (as with many Adventurous Activities) please supply it as a Supporting Doc. Add a note in an empty row in the Risks tab with the name of the doc | D19: Email any supporting docs to risk@scoutswa.com.au or your line leader
B20: Your controls must have an effect to modify the Consequence and Likelihood values, otherwise why have them?
A22: Dos and Don'ts
B23: Don't merge or insert cells.
B24: Do place any notes in the comments box AFTER the list of risks.
B25: Don't leave any blank or empty lines. All risks to be in sequence from .01 onwards.

Sheet Risk Matrix
D2: Consequence | J2: CONTROLS
D3: Insignificant - A | E3: Minor - B | F3: Moderate - C | G3: Major - D | H3: Catastrophic - E | J3: BEST
B4: LIKELIHOOD | C4: Very Unlikely - A | D4: AA - Risk acceptable | E4: AB - Risk acceptable | F4: AC - Risk acceptable | G4: AD - Review at appropriate times | H4: AE - Review at appropriate times | J4: Elimination
C5: Unlikely - B | D5: BA - Risk acceptable | E5: BB - Risk acceptable | F5: BC - Review at appropriate times | G5: BD - Review at appropriate times | H5: BE - High priority | J5: Substitution
C6: Possible - C | D6: CA - Risk acceptable | E6: CB - Review at appropriate times | F6: CC - Review at appropriate times | G6: CD - High priority | H6: CE - Unacceptable Risk, immediate action required | J6: Isolation
C7: Likely - D | D7: DA - Risk acceptable | E7: DB - Review at appropriate times | F7: DC - High priority | G7: DD - Unacceptable Risk, immediate action required | H7: DE - Unacceptable Risk, immediate action required | J7: Engineering
C8: Very Likely - E | D8: EA - Review at appropriate times | E8: EB - High priority | F8: EC - Unacceptable Risk, immediate action required | G8: ED - Unacceptable Risk, immediate action required | H8: EE - Unacceptable Risk, immediate action required | J8: Administrative
J9: PPE
C10: ScoutsWA Incident and Severity Table: | J10: WORST
C11: https://scoutswa.com.au/wp-content/uploads/2023/08/Risk-Matrix_For-Incident-Report-System.pdf

Sheet Event Details
B3: Formations Attending
C4: Group (Click on the arrow to choose) | E4: District | F4: Region
B5: Add Formations | C5: Choose your Group... | E5: =IFERROR((VLOOKUP($C5,Lookups!$C$6:$E$155,2,FALSE)), "") | F5: =IFERROR((VLOOKUP($C5,Lookups!$C$6:$E$155,3,FALSE)), "")
C6: Choose your Group... | E6: =IFERROR((VLOOKUP($C6,Lookups!$C$6:$E$155,2,FALSE)), "") | F6: =IFERROR((VLOOKUP($C6,Lookups!$C$6:$E$155,3,FALSE)), "")
C7: Choose your Group... | E7: =IFERROR((VLOOKUP($C7,Lookups!$C$6:$E$155,2,FALSE)), "") | F7: =IFERROR((VLOOKUP($C7,Lookups!$C$6:$E$155,3,FALSE)), "")
C8: Choose your Group... | F8: =IFERROR((VLOOKUP($C8,Lookups!$C$6:$E$155,3,FALSE)), "")
C9: Choose your Group... | E9: =IFERROR((VLOOKUP($C9,Lookups!$C$6:$E$155,2,FALSE)), "") | F9: =IFERROR((VLOOKUP($C9,Lookups!$C$6:$E$155,3,FALSE)), "")
B11: Sections(s) | C11: Joeys | H11: R1
C12: Cubs
C13: Scouts
C14: Venturers
C15: Rovers
C16: Leaders | H16: V20230908
B19: Activity Details
B21: Type of activity | C21: Choose the activity...
B22: Major outing/Camp/Hike/Sleepover/etc
B23: Event name
B25: Location
B27: Venue Address
B29: Commencing on | E29: at Time
C30: dd/mm/yyyy | F30: 24 hour time hh:mm or type am/pm
B31: Concluding on | E31: at Time
C33: =IFERROR(CONCATENATE("Event start date is ",MROUND(DATEDIF(TODAY(),C29,"d")/7,1), " weeks away."),"")
B36: Personnel details - | C36: Start with the main organiser, then add others as needed. Each person can have multiple roles
C37: Person in charge name | E37: Membership No. | F37: Appointment | G37: Email address
C39: Person in charge of event | G39: Phone number
B40: Add your other roles ----> | C40: choose your role…
C41: choose your role…
C42: choose your role…
C44: Name | E44: Membership No. | F44: Appointment | G44: Email address
B46: Change if needed ----> | C46: choose your role… | G46: Phone number
C47: choose your role…
C48: choose your role…
C49: choose your role…
C51: Name | E51: Membership No. | F51: Appointment | G51: Email address
B53: Change if needed ----> | C53: choose your role… | G53: Phone number
C54: choose your role…
C55: choose your role…
C56: choose your role…
C58: Name | E58: Membership No. | F58: Appointment | G58: Email address
...

Sheet Event Risks
A2: Event Risks
A3: C = Consequence. L = Likelihood. See Risk matrix below.
A4: ANALYSE & ASSESS RISKS | G4: MANAGE THE RISKS
A5: ID | B5: HAZARD (WHAT) | C5: INJURY/DANGER (WHO) | D5: C | E5: L | F5: RISK RATING | G5: CONTROLS | H5: NEW C | I5: NEW L | J5: RESIDUAL RISK RATING
A6: eg | B6: Tent rope | C6: Trip - cuts and grazes | D6: B | E6: D | F6: HIGH | G6: Tent ropes set out in expected locations - if not, flagged with warning tape. Remind Scouts to be aware when moving around tents. | H6: B | I6: A | J6: LOW
A7: eg | B7: Sun - ultra violet radiation | C7: Sunburn | D7: C | E7: B | F7: MEDIUM | G7: Slip, slop, slap - use ScoutsWA Sun Smart procedure | H7: A | I7: A | J7: LOW
A8: E.01 | F8: =IFERROR(VLOOKUP(_xlfn.CONCAT(D8,E8),Lookups!$Y$5:$Z$29,2,FALSE),"") | J8: =IFERROR(VLOOKUP(_xlfn.CONCAT(H8,I8),Lookups!$Y$5:$Z$29,2,FALSE),"")
A9: E.02 | F9: =IFERROR(VLOOKUP(_xlfn.CONCAT(D9,E9),Lookups!$Y$5:$Z$29,2,FALSE),"") | J9: =IFERROR(VLOOKUP(_xlfn.CONCAT(H9,I9),Lookups!$Y$5:$Z$29,2,FALSE),"")
A10: E.03 | F10: =IFERROR(VLOOKUP(_xlfn.CONCAT(D10,E10),Lookups!$Y$5:$Z$29,2,FALSE),"") | J10: =IFERROR(VLOOKUP(_xlfn.CONCAT(H10,I10),Lookups!$Y$5:$Z$29,2,FALSE),"")
A11: E.04 | F11: =IFERROR(VLOOKUP(_xlfn.CONCAT(D11,E11),Lookups!$Y$5:$Z$29,2,FALSE),"") | J11: =IFERROR(VLOOKUP(_xlfn.CONCAT(H11,I11),Lookups!$Y$5:$Z$29,2,FALSE),"")
A12: E.05 | F12: =IFERROR(VLOOKUP(_xlfn.CONCAT(D12,E12),Lookups!$Y$5:$Z$29,2,FALSE),"") | J12: =IFERROR(VLOOKUP(_xlfn.CONCAT(H12,I12),Lookups!$Y$5:$Z$29,2,FALSE),"")
A13: E.06 | F13: =IFERROR(VLOOKUP(_xlfn.CONCAT(D13,E13),Lookups!$Y$5:$Z$29,2,FALSE),"") | J13: =IFERROR(VLOOKUP(_xlfn.CONCAT(H13,I13),Lookups!$Y$5:$Z$29,2,FALSE),"")
A14: E.07 | F14: =IFERROR(VLOOKUP(_xlfn.CONCAT(D14,E14),Lookups!$Y$5:$Z$29,2,FALSE),"") | J14: =IFERROR(VLOOKUP(_xlfn.CONCAT(H14,I14),Lookups!$Y$5:$Z$29,2,FALSE),"")
A15: E.08 | F15: =IFERROR(VLOOKUP(_xlfn.CONCAT(D15,E15),Lookups!$Y$5:$Z$29,2,FALSE),"") | J15: =IFERROR(VLOOKUP(_xlfn.CONCAT(H15,I15),Lookups!$Y$5:$Z$29,2,FALSE),"")
A16: E.09 | F16: =IFERROR(VLOOKUP(_xlfn.CONCAT(D16,E16),Lookups!$Y$5:$Z$29,2,FALSE),"") | J16: =IFERROR(VLOOKUP(_xlfn.CONCAT(H16,I16),Lookups!$Y$5:$Z$29,2,FALSE),"")
A17: E.10 | F17: =IFERROR(VLOOKUP(_xlfn.CONCAT(D17,E17),Lookups!$Y$5:$Z$29,2,FALSE),"") | J17: =IFERROR(VLOOKUP(_xlfn.CONCAT(H17,I17),Lookups!$Y$5:$Z$29,2,FALSE),"")
A18: E.11 | F18: =IFERROR(VLOOKUP(_xlfn.CONCAT(D18,E18),Lookups!$Y$5:$Z$29,2,FALSE),"") | J18: =IFERROR(VLOOKUP(_xlfn.CONCAT(H18,I18),Lookups!$Y$5:$Z$29,2,FALSE),"")
A19: E.12 | F19: =IFERROR(VLOOKUP(_xlfn.CONCAT(D19,E19),Lookups!$Y$5:$Z$29,2,FALSE),"") | J19: =IFERROR(VLOOKUP(_xlfn.CONCAT(H19,I19),Lookups!$Y$5:$Z$29,2,FALSE),"")
... A27: E.20 | F27: =IFERROR(VLOOKUP(_xlfn.CONCAT(D27,E27),Lookups!$Y$5:$Z$29,2,FALSE),"") | J27: =IFERROR(VLOOKUP(_xlfn.CONCAT(H27,I27),Lookups!$Y$5:$Z$29,2,FALSE),"")
G28: Highest Residual risk ---> | J28: {=IFERROR(_xlfn.IFS(COUNTIF(J8:J27,"VERY HIGH")>0,"VERY HIGH",COUNTIF(J8:J27,"HIGH")>0,"HIGH",COUNTIF(J8:J27,"MEDIUM")>0,"MEDIUM",COUNTIF(J8:J27,"LOW")>0,"LOW"),"")}
A29: COMMENTS, Insurance info, etc

Sheet Activity Risks
G2: Activity Name
B3: Brief description of the activity:
B4: C = Consequence. L = Likelihood. See Risk matrix below.
B5: ANALYSE & ASSESS RISKS | H5: MANAGE THE RISKS
B6: ID | C6: HAZARD (WHAT) | D6: INJURY/DANGER (WHO) | E6: C | F6: L | G6: RISK RATING | H6: CONTROLS | I6: NEW C | J6: NEW L | K6: RESIDUAL RISK RATING
B7: eg | C7: Tent rope | D7: Trip - cuts and grazes | E7: B | F7: D | G7: HIGH | H7: Tent ropes set out in expected locations - if not, flagged with warning tape. Remind Scouts to be aware when moving around tents. | I7: B | J7: A | K7: LOW
B8: eg | C8: Sun - ultra violet radiation | D8: Sunburn | E8: C | F8: B | G8: MEDIUM | H8: Slip, slop, slap - use ScoutsWA Sun Smart procedure | I8: A | J8: A | K8: LOW
B9: 1.01 | D9: wasds | E9: C | F9: C | G9: =IFERROR(VLOOKUP(_xlfn.CONCAT(E9,F9),Lookups!$Y$5:$Z$29,2,FALSE),"") -> MEDIUM | K9: =IFERROR(VLOOKUP(_xlfn.CONCAT(I9,J9),Lookups!$Y$5:$Z$29,2,FALSE),"")
B10: 1.02 | G10: =IFERROR(VLOOKUP(_xlfn.CONCAT(E10,F10),Lookups!$Y$5:$Z$29,2,FALSE),"") | K10: =IFERROR(VLOOKUP(_xlfn.CONCAT(I10,J10),Lookups!$Y$5:$Z$29,2,FALSE),"")
B11: 1.03 | G11: =IFERROR(VLOOKUP(_xlfn.CONCAT(E11,F11),Lookups!$Y$5:$Z$29,2,FALSE),"") | K11: =IFERROR(VLOOKUP(_xlfn.CONCAT(I11,J11),Lookups!$Y$5:$Z$29,2,FALSE),"")
B12: 1.04 | G12: =IFERROR(VLOOKUP(_xlfn.CONCAT(E12,F12),Lookups!$Y$5:$Z$29,2,FALSE),"") | K12: =IFERROR(VLOOKUP(_xlfn.CONCAT(I12,J12),Lookups!$Y$5:$Z$29,2,FALSE),"")
B13: 1.05 | G13: =IFERROR(VLOOKUP(_xlfn.CONCAT(E13,F13),Lookups!$Y$5:$Z$29,2,FALSE),"") | K13: =IFERROR(VLOOKUP(_xlfn.CONCAT(I13,J13),Lookups!$Y$5:$Z$29,2,FALSE),"")
B14: 1.06 | G14: =IFERROR(VLOOKUP(_xlfn.CONCAT(E14,F14),Lookups!$Y$5:$Z$29,2,FALSE),"") | K14: =IFERROR(VLOOKUP(_xlfn.CONCAT(I14,J14),Lookups!$Y$5:$Z$29,2,FALSE),"")
B15: 1.07 | G15: =IFERROR(VLOOKUP(_xlfn.CONCAT(E15,F15),Lookups!$Y$5:$Z$29,2,FALSE),"") | K15: =IFERROR(VLOOKUP(_xlfn.CONCAT(I15,J15),Lookups!$Y$5:$Z$29,2,FALSE),"")
B16: 1.08 | G16: =IFERROR(VLOOKUP(_xlfn.CONCAT(E16,F16),Lookups!$Y$5:$Z$29,2,FALSE),"") | K16: =IFERROR(VLOOKUP(_xlfn.CONCAT(I16,J16),Lookups!$Y$5:$Z$29,2,FALSE),"")
B17: 1.09 | G17: =IFERROR(VLOOKUP(_xlfn.CONCAT(E17,F17),Lookups!$Y$5:$Z$29,2,FALSE),"") | K17: =IFERROR(VLOOKUP(_xlfn.CONCAT(I17,J17),Lookups!$Y$5:$Z$29,2,FALSE),"")
B18: 1.1 | G18: =IFERROR(VLOOKUP(_xlfn.CONCAT(E18,F18),Lookups!$Y$5:$Z$29,2,FALSE),"") | K18: =IFERROR(VLOOKUP(_xlfn.CONCAT(I18,J18),Lookups!$Y$5:$Z$29,2,FALSE),"")
B19: 1.11 | G19: =IFERROR(VLOOKUP(_xlfn.CONCAT(E19,F19),Lookups!$Y$5:$Z$29,2,FALSE),"") | K19: =IFERROR(VLOOKUP(_xlfn.CONCAT(I19,J19),Lookups!$Y$5:$Z$29,2,FALSE),"")
B20: 1.12 | G20: =IFERROR(VLOOKUP(_xlfn.CONCAT(E20,F20),Lookups!$Y$5:$Z$29,2,FALSE),"") | K20: =IFERROR(VLOOKUP(_xlfn.CONCAT(I20,J20),Lookups!$Y$5:$Z$29,2,FALSE),"")
B21: 1.13 | G21: =IFERROR(VLOOKUP(_xlfn.CONCAT(E21,F21),Lookups!$Y$5:$Z$29,2,FALSE),"") | K21: =IFERROR(VLOOKUP(_xlfn.CONCAT(I21,J21),Lookups!$Y$5:$Z$29,2,FALSE),"")
... B28: 1.2 | G28: =IFERROR(VLOOKUP(_xlfn.CONCAT(E28,F28),Lookups!$Y$5:$Z$29,2,FALSE),"") | K28: =IFERROR(VLOOKUP(_xlfn.CONCAT(I28,J28),Lookups!$Y$5:$Z$29,2,FALSE),"")
H29: Highest Residual risk ---> | K29: {=IFERROR(_xlfn.IFS(COUNTIF(K9:K28,"VERY HIGH")>0,"VERY HIGH",COUNTIF(K9:K28,"HIGH")>0,"HIGH",COUNTIF(K9:K28,"MEDIUM")>0,"MEDIUM",COUNTIF(K9:K28,"LOW")>0,"LOW"),"")}
B30: COMMENTS, Insurance info, etc

Sheet Sign-off
C3: Event name | D3: =IF('Event Details'!C23="","",'Event Details'!C23)
C4: Date | D4: =IF('Event Details'!C29="","",'Event Details'!C29)
C5: Highest Residual Risk overall from Event and activities | D5: {=IFERROR(_xlfn.IFS(OR('Event Risks'!J28="VERY HIGH",'Activity Risks'!K29="VERY HIGH"),"VERY HIGH", OR('Event Risks'!J28="HIGH",'Activity Risks'!K29="HIGH"),"HIGH", OR('Event Risks'!J28="MEDIUM",'Activity Risks'!K29="MEDIUM"),"MEDIUM", OR('Event Risks'!J28="LOW",'Activity Risks'!K29="LOW"),"LOW"), "")}
B7: Leader in charge (or Leader responsible, if activity is being run by a youth member)
B8: I confirm that all participants including Parents/Guardians of youth participants involved in this activity will be advised in writing of the activity and permission will be obtained before the activity commences.
B9: I have reviewed and completed the ‘Risk Management Plan’ (attached) for all aspects of the planned activity and control measures will be implemented prior to the activity commencing.
B10: I also confirm that the supervisors of each Adventurous Activity component are either registered as Activity Leaders with the Association and have completed a ‘Risk Management Plan’ or have provided their Public Liability Insurance Certificate of Currency.
B11: Name | C11: =IF('Event Details'!C38=0,"",'Event Details'!C38) | D11: Signed (if paper form)
B12: Date
B13: Membership Number | C13: =IF('Event Details'!E38=0,"",'Event Details'!E38)
B15: Formation leader
B16: I approve the activity and confirm that the Leader responsible will collect permission forms two weeks prior to the commencement of the activity and that a ‘Risk Management Plan’ has been undertaken and that control measures have been identified.
B17: Name | D17: Signed (if paper form)
B18: Date
B19: Membership Number
B21: District Commissioner / Branch Commissioner
B22: I have checked the attached details and approve the ‘Risk Management Plan’ that the Leader Responsible has undertaken for this activity and that control measures have been identified.
B23: Name | D23: Signed (if paper form)
B24: Date
B25: Membership Number
B27: Regional Chief Commissioner / Deputy Chief Commissioner
B28: I have checked the attached details and approve the ‘Risk Management Plan’ that the Leader Responsible has undertaken for this activity and that control measures have been identified.
B29: Name | D29: Signed (if paper form)
B30: Date
B31: Membership Number

Sheet Lookups
V1: 1
V2: 2
C3: Locations | E3: F5:F153 | I3: Yes/No | L3: C&L #s | O3: Sections | R3: Roles | U3: Scope | V3: 3 | Y3: CL | Z3: Risk Rating
C4: Group | D4: District | E4: Region | V4: 4
C5: Choose your Group... | I5: Yes | L5: A | O5: Joeys | R5: choose your role… | U5: Group | V5: 5 | Y5: AA | Z5: LOW
C6: all Scouts WA | D6: Please contact | E6: ScoutsWA Events Coordinator for more info. | I6: No | L6: B | O6: Cubs | R6: Event coordinator | U6: District | V6: 6 | Y6: AB | Z6: LOW
C7: all Perth South region | D7: Please contact | E7: ScoutsWA Events Coordinator for more info. | L7: C | O7: Scouts | R7: Event 2IC | U7: Region | V7: 7 | Y7: AC | Z7: LOW
C8: all Beeliar District | D8: Beeliar District | E8: Perth South Region | L8: D | O8: Venturers | R8: First Aid | U8: Branch | V8: 8 | Y8: AD | Z8: MEDIUM
C9: Atwell | D9: Beeliar District | E9: Perth South Region | L9: E | O9: Rovers | R9: Security | U9: Interstate | V9: 9 | Y9: AE | Z9: MEDIUM
C10: Bibra Lake | D10: Beeliar District | E10: Perth South Region | R10: Treasurer | U10: International | V10: 10 | Y10: BA | Z10: LOW
C11: Fremantle Sea Scouts | D11: Beeliar District | E11: Perth South Region | R11: Registration | V11: 11 | Y11: BB | Z11: LOW
C12: Jervoise Bay | D12: Beeliar District | E12: Perth South Region | R12: Administration | V12: 12 | Y12: BC | Z12: MEDIUM
C13: all Beeloo District | D13: Beeloo District | E13: Perth South Region | R13: Risk Management | V13: 13 | Y13: BD | Z13: MEDIUM
C14: Carlisle | D14: Beeloo District | E14: Perth South Region | R14: Leader in charge | V14: 14 | Y14: BE | Z14: HIGH
C15: Salter Point Sea Scouts | D15: Beeloo District | E15: Perth South Region | I15: Activity | L15: Risk Level | R15: Formation Leader | V15: 15 | Y15: CA | Z15: LOW
C16: Victoria Park | D16: Beeloo District | E16: Perth South Region | R16: Group Leader | V16: 16 | Y16: CB | Z16: MEDIUM
C17: all Canning River District | D17: Canning River District | E17: Perth South Region | I17: Choose the activity... | L17: Very High | R17: District Commissioner | V17: 17 | Y17: CC | Z17: MEDIUM
C18: Canning Sea Scouts | D18: Canning River District | E18: Perth South Region | I18: Major Event | L18: High | R18: Service coordinator | V18: 18 | Y18: CD | Z18: HIGH
C19: Riverton | D19: Canning River District | E19: Perth South Region | I19: Major outing | L19: Medium | R19: Onsite activities | V19: 19 | Y19: CE | Z19: VERY HIGH
C20: Rossmoyne Shelley | D20: Canning River District | E20: Perth South Region | I20: Camp | L20: Low | R20: Offsite activities | V20: 20 | Y20: DA | Z20: MEDIUM
C21: Whaleback | D21: Canning River District | E21: Perth South Region | I21: Hike | R21: Adventurous activities | V21: 21 | Y21: DB | Z21: MEDIUM
C22: Willetton | D22: Canning River District | E22: Perth South Region | I22: Sleepover | R22: PR officer | V22: 22 | Y22: DC | Z22: HIGH
C23: all Melville District | D23: Melville District | E23: Perth South Region | I23: Other | R23: AA Leader | V23: 23 | Y23: DD | Z23: VERY HIGH
C24: Attadale | D24: Melville District | E24: Perth South Region | R24: Person in charge | V24: 24 | Y24: DE | Z24: VERY HIGH
C25: Bateman Winthrop | D25: Melville District | E25: Perth South Region | R25: Welfare | V25: 25 | Y25: EA | Z25: MEDIUM
C26: Bullcreek Leeming | D26: Melville District | E26: Perth South Region | I26: R1 Highest Residual test | L26: R2 Highest Residual | O26: R3 Highest Residual | R26: Logistics | V26: 26 | Y26: EB | Z26: HIGH
C27: Waylen Bay Sea Scouts | D27: Melville District | E27: Perth South Region | R27: Other | V27: 27 | Y27: EC | Z27: VERY HIGH
C28: Willagee Kardinya | D28: Melville District | E28: Perth South Region | H28: E | I28: {=ISTEXT(INDEX(J$9:J$28, MATCH("ver*", J$9:J$28, 0), 1))} -> FALSE | K28: E | L28: ISTEXT(INDEX($K$9:$K$28, MATCH("ver*", $K$9:$K$28, 0), 1)) | V28: 28 | Y28: ED | Z28: VERY HIGH
C29: all Minnawarra District | D29: Minnawarra District | E29: Perth South Region | K29: E | L29: {=ISTEXT(INDEX(J$9:J$28, MATCH("hig*", J$9:J$28, 0), 1))} -> FALSE | V29: 29 | Y29: EE | Z29: VERY HIGH
C30: Armadale | D30: Minnawarra District | E30: Perth South Region | K30: E | L30: {=ISTEXT(INDEX(J$9:J$28, MATCH("med*", J$9:J$28, 0), 1))} -> FALSE | V30: 30
C31: Byford | D31: Minnawarra District | E31: Perth South Region | K31: E | L31: {=ISTEXT(INDEX(J$9:J$28, MATCH("lo*", J$9:J$28, 0), 1))} -> FALSE | V31: 31
C32: Kelmscott | D32: Minnawarra District | E32: Perth South Region | V32: 32
C33: Roleystone | D33: Minnawarra District | E33: Perth South Region | V33: 33
C34: Westfield | D34: Minnawarra District | E34: Perth South Region | V34: 34
C35: all Osprey District | D35: Osprey District | E35: Perth South Region | V35: 35
C36: Baldivis | D36: Osprey District | E36: Perth South Region | V36: 36
C37: Kwinana | D37: Osprey District | E37: Perth South Region | V37: 37
C38: Rockingham | D38: Osprey District | E38: Perth South Region | V38: 38
C39: Secret Harbour | D39: Osprey District | E39: Perth South Region | V39: 39
C40: Warnbro Sound | D40: Osprey District | E40: Perth South Region | V40: 40
...
